Workbook

Sheet Readme
B1: SIM data validation - working demo
B3: What to try
B4: Go to the 'query' sheet and edit PhoneNr, ICC_ID, StartDate, Status, SIM Type or IMEI. Valid entries turn green, broken ones red, and the matching check column tells you exactly what is wrong. RowErrors (column AB) collects every problem in the row on one line.
B5: The 33 sample rows exercise every rule. The grey notes to the right of the table say what each row is testing - delete that column and the sample rows before you use this for real.
B7: Colour code - the same three colours everywhere
B8: Green = OK
B9: Red = the value is wrong and someone has to fix it
B10: Amber = WARNING. Probably wrong, but not certainly - see below.
B11: Every warning message starts with the literal text 'WARNING:', and that prefix is what the amber conditional-formatting rule tests. If you add your own warnings later, keep the prefix and they will colour themselves.
B13: PhoneNr -> IsPhoneValid (col T), via PhoneClean (col V)
B14: Strips + space nbsp - ( ) . and converts a leading 00 to bare digits.
B15: Digits only, then length 8-15, then must start with the SIM_Country dial code.
... B62: No uniqueness check on ICC_ID, IMEI, PhoneNr or ID. Say the word - it is a COUNTIF away.

Sheet Config
A1: Name | B1: Alpha2 | C1: Alpha3 | D1: Num | E1: DialCode | G1: Status (allowed) | H1: SIM Type (allowed)
A2: Australia | B2: AU | C2: AUS | D2: 36 | E2: 61 | G2: Active | H2: eSIM
A3: Austria | B3: AT | C3: AUT | D3: 40 | E3: 43 | G3: Deactivated | H3: Physical SIM
A4: Belgium | B4: BE | C4: BEL | D4: 56 | E4: 32 | G4: Suspended
A5: Brazil | B5: BR | C5: BRA | D5: 76 | E5: 55
A6: Bulgaria | B6: BG | C6: BGR | D6: 100 | E6: 359 | G6: These two lists are referenced by the dropdowns and the check formulas
A7: Canada | B7: CA | C7: CAN | D7: 124 | E7: 1 | G7: on the query sheet. Edit the values here, not on the query sheet.
A8: China | B8: CN | C8: CHN | D8: 156 | E8: 86
A9: Croatia | B9: HR | C9: HRV | D9: 191 | E9: 385
A10: Cyprus | B10: CY | C10: CYP | D10: 196 | E10: 357
A11: Czechia | B11: CZ | C11: CZE | D11: 203 | E11: 420
A12: Denmark | B12: DK | C12: DNK | D12: 208 | E12: 45
A13: Estonia | B13: EE | C13: EST | D13: 233 | E13: 372
A14: Finland | B14: FI | C14: FIN | D14: 246 | E14: 358
A15: France | B15: FR | C15: FRA | D15: 250 | E15: 33
A16: Germany | B16: DE | C16: DEU | D16: 276 | E16: 49
A17: Greece | B17: GR | C17: GRC | D17: 300 | E17: 30
A18: Hong Kong | B18: HK | C18: HKG | D18: 344 | E18: 852
A19: Hungary | B19: HU | C19: HUN | D19: 348 | E19: 36
... A51: United States | B51: US | C51: USA | D51: 840 | E51: 1

Sheet query
A1: FirstName | B1: LastName | C1: PhoneNr | D1: Plan | E1: ICC_ID | F1: GD_ID | G1: StartDate | H1: SIM_Country | I1: Provider | J1: CostCenter | K1: UBR_Code | L1: Legal entity | M1: IsVR | N1: BAN | O1: SOC | P1: Status | Q1: SIM Type | R1: Email | S1: ID | T1: IsPhoneValid | U1: IMEI | V1: PhoneClean | W1: ICC_Check | X1: IMEI_Check | Y1: Date_Check | Z1: Status_Check | AA1: SIMType_Check | AB1: RowErrors | AD1: Test case (not part of the table - delete when you are done)
A2: Ana | B2: Popescu | C2: +40712345678 | E2: 8935201234567890125 | G2: 15-03-2026 | H2: Romania | P2: Active | Q2: eSIM | T2: =IF($C2="","",IF($V2="","No digits at all - enter a phone number",IF(NOT(SUMPRODUCT(--ISNUMBER(--MID($V2,ROW(INDIRECT("1:"&LEN($V2))),1)))=LEN($V2)),"Digits only - no letters or symbols (+ ( ) - . and spaces are tolerated)",IF(LEN($V2)<8,"Too short - "&LEN($V2)&" digits (min 8)",IF(LEN($V2)>15,"Too long - "&LEN($V2)&" digits (max 15)",IF($H2="","WARNING: SIM_Country is empty - cannot check the country code",IF(ISNA(MATCH($H2,tblCountries[Name],0)),"WARNING: SIM_Country """&$H2&""" is not in tblCountries",IF(LEFT($V2,LEN(TEXT(INDEX(tblCountries[DialCode],MATCH($H2,tblCountries[Name],0)),"0")))<>TEXT(INDEX(tblCountries[DialCode],MATCH($H2,tblCountries[Name],0)),"0"),"Wrong country code - must start with +"&TEXT(INDEX(tblCountries[DialCode],MATCH($H2,tblCountries[Name],0)),"0")&" for "&$H2,"OK")))))))) -> OK | U2: 352099001760897 | V2: =IF($C2="","",IF(LEFT(SUBSTITUTE(SUBSTITUTE(SUBSTITUTE(SUBSTITUTE(SUBSTITUTE(SUBSTITUTE(SUBSTITUTE(TRIM($C2&""),"+","")," ",""),"-",""),"(",""),")",""),".",""),CHAR(160),""),2)="00",MID(SUBSTITUTE(SUBSTITUTE(SUBSTITUTE(SUBSTITUTE(SUBSTITUTE(SUBSTITUTE(SUBSTITUTE(TRIM($C2&""),"+","")," ",""),"-",""),"(",""),")",""),".",""),CHAR(160),""),3,255),SUBSTITUTE(SUBSTITUTE(SUBSTITUTE(SUBSTITUTE(SUBSTITUTE(SUBSTITUTE(SUBSTITUTE(TRIM($C2&""),"+","")," ",""),"-",""),"(",""),")",""),".",""),CHAR(160),""))) -> 40712345678 | W2: =IF($E2="","",IF(ISNUMBER($E2),"Stored as a NUMBER - every digit past the 15th is already lost. Format the column as Text and re-enter.",IF(NOT(SUMPRODUCT(--ISNUMBER(--MID(TRIM($E2&""),ROW(INDIRECT("1:"&LEN(TRIM($E2&"")))),1)))=LEN(TRIM($E2&""))),"Digits only - no +, -, spaces or any other character",IF(LEFT(TRIM($E2&""),2)<>"89","Must start with 89 (ITU-T E.118 telecom prefix)",IF(LEN(TRIM($E2&""))<18,"Too short - "&LEN(TRIM($E2&""))&" digits (min 18)",IF(LEN(TRIM($E2&""))>22,"Too long - "&LEN(TRIM($E2&""))&" digits (max 22)",IF(NOT(MOD(SUMPRODUCT(MID(TRIM($E2&""),ROW(INDIRECT("1:"&LEN(TRIM($E2&"")))),1)*1*(1+MOD(LEN(TRIM($E2&""))-ROW(INDIRECT("1:"&LEN(TRIM($E2&"")))),2))-MOD(LEN(TRIM($E2&""))-ROW(INDIRECT("1:"&LEN(TRIM($E2&"")))),2)*9*(MID(TRIM($E2&""),ROW(INDIRECT("1:"&LEN(TRIM($E2&"")))),1)*1*2>9)),10)=0),"WARNING: Luhn check digit does not match - likely a typo or a transposition","OK"))))))) -> OK | X2: =IF($U2="","",IF(NOT(SUMPRODUCT(--ISNUMBER(--MID(TRIM($U2&""),ROW(INDIRECT("1:"&LEN(TRIM($U2&"")))),1)))=LEN(TRIM($U2&""))),"Digits only - no +, -, spaces or any other character",IF(LEN(TRIM($U2&""))<>15,"Must be exactly 15 digits - this one has "&LEN(TRIM($U2&"")),IF(NOT(MOD(SUMPRODUCT(MID(TRIM($U2&""),ROW(INDIRECT("1:"&LEN(TRIM($U2&"")))),1)*1*(1+MOD(LEN(TRIM($U2&""))-ROW(INDIRECT("1:"&LEN(TRIM($U2&"")))),2))-MOD(LEN(TRIM($U2&""))-ROW(INDIRECT("1:"&LEN(TRIM($U2&"")))),2)*9*(MID(TRIM($U2&""),ROW(INDIRECT("1:"&LEN(TRIM($U2&"")))),1)*1*2>9)),10)=0),"WARNING: Luhn check digit does not match - likely a typo or a transposition","OK")))) -> OK | Y2: =IF($G2="","",IF(ISNUMBER($G2),IF(OR($G2<DATE(2000,1,1),$G2>TODAY()+730),"WARNING: real date, but outside 2000-01-01 .. today+2y - check the day/month order","OK"),IF(LEN(TRIM($G2&""))<>10,"Must be dd-mm-yyyy - 10 characters, this one has "&LEN(TRIM($G2&"")),IF(AND(NOT(ISERROR(FIND(MID(TRIM($G2&""),5,1),"-/."))),NOT(ISERROR(FIND(MID(TRIM($G2&""),8,1),"-/."))),SUMPRODUCT(--ISNUMBER(--MID(LEFT(TRIM($G2&""),4),ROW(INDIRECT("1:"&LEN(LEFT(TRIM($G2&""),4)))),1)))=LEN(LEFT(TRIM($G2&""),4))),"Looks like yyyy-mm-dd - StartDate must put the DAY first: dd-mm-yyyy",IF(OR(MID(TRIM($G2&""),3,1)<>MID(TRIM($G2&""),6,1),ISERROR(FIND(MID(TRIM($G2&""),3,1),"-/."))),"Separators must be in positions 3 and 6, matching, and be - or / or .",IF(NOT(AND(SUMPRODUCT(--ISNUMBER(--MID(LEFT(TRIM($G2&""),2),ROW(INDIRECT("1:"&LEN(LEFT(TRIM($G2&""),2)))),1)))=LEN(LEFT(TRIM($G2&""),2)),SUMPRODUCT(--ISNUMBER(--MID(MID(TRIM($G2&""),4,2),ROW(INDIRECT("1:"&LEN(MID(TRIM($G2&""),4,2)))),1)))=LEN(MID(TRIM($G2&""),4,2)),SUMPRODUCT(--ISNUMBER(--MID(RIGHT(TRIM($G2&""),4),ROW(INDIRECT("1:"&LEN(RIGHT(TRIM($G2&""),4)))),1)))=LEN(RIGHT(TRIM($G2&""),4)))),"Day, month and year must all be digits",IF(OR(LEFT(TRIM($G2&""),2)*1<1,LEFT(TRIM($G2&""),2)*1>31),"Day out of range - dd-mm-yyyy puts the DAY first",IF(OR(MID(TRIM($G2&""),4,2)*1<1,MID(TRIM($G2&""),4,2)*1>12),"Month out of range - dd-mm-yyyy puts the MONTH second",IF(OR(RIGHT(TRIM($G2&""),4)*1<2000,RIGHT(TRIM($G2&""),4)*1>2100),"Year out of range (2000-2100)",IF(DAY(DATE(RIGHT(TRIM($G2&""),4)*1,MID(TRIM($G2&""),4,2)*1,LEFT(TRIM($G2&""),2)*1))<>LEFT(TRIM($G2&""),2)*1,"Not a real calendar date (e.g. 31-02 or 30-02)","OK")))))))))) -> OK | Z2: =IF($P2="","",IF(SUMPRODUCT(--EXACT($P2,Config!$G$2:$G$4))>0,"OK",IF(NOT(ISNA(MATCH($P2,Config!$G$2:$G$4,0))),"WARNING: wrong capitalisation - should be """&INDEX(Config!$G$2:$G$4,MATCH($P2,Config!$G$2:$G$4,0))&""" exactly","Must be one of: Active, Deactivated, Suspended"))) -> OK | AA2: =IF($Q2="","",IF(SUMPRODUCT(--EXACT($Q2,Config!$H$2:$H$3))>0,"OK",IF(NOT(ISNA(MATCH($Q2,Config!$H$2:$H$3,0))),"WARNING: wrong capitalisation - should be """&INDEX(Config!$H$2:$H$3,MATCH($Q2,Config!$H$2:$H$3,0))&""" exactly","Must be one of: eSIM, Physical SIM"))) -> OK | AB2: =IF(IF(OR($T2="",$T2="OK"),"","PhoneNr: "&$T2&" // ")&IF(OR($W2="",$W2="OK"),"","ICC_ID: "&$W2&" // ")&IF(OR($Y2="",$Y2="OK"),"","StartDate: "&$Y2&" // ")&IF(OR($Z2="",$Z2="OK"),"","Status: "&$Z2&" // ")&IF(OR($AA2="",$AA2="OK"),"","SIM Type: "&$AA2&" // ")&IF(OR($X2="",$X2="OK"),"","IMEI: "&$X2&" // ")="","OK",LEFT(IF(OR($T2="",$T2="OK"),"","PhoneNr: "&$T2&" // ")&IF(OR($W2="",$W2="OK"),"","ICC_ID: "&$W2&" // ")&IF(OR($Y2="",$Y2="OK"),"","StartDate: "&$Y2&" // ")&IF(OR($Z2="",$Z2="OK"),"","Status: "&$Z2&" // ")&IF(OR($AA2="",$AA2="OK"),"","SIM Type: "&$AA2&" // ")&IF(OR($X2="",$X2="OK"),"","IMEI: "&$X2&" // "),LEN(IF(OR($T2="",$T2="OK"),"","PhoneNr: "&$T2&" // ")&IF(OR($W2="",$W2="OK"),"","ICC_ID: "&$W2&" // ")&IF(OR($Y2="",$Y2="OK"),"","StartDate: "&$Y2&" // ")&IF(OR($Z2="",$Z2="OK"),"","Status: "&$Z2&" // ")&IF(OR($AA2="",$AA2="OK"),"","SIM Type: "&$AA2&" // ")&IF(OR($X2="",$X2="OK"),"","IMEI: "&$X2&" // "))-6)) -> OK | AD2: PhoneNr: valid, + prefix
A3: Mihai | B3: Ionescu | C3: 40712345678 | E3: 893520123456789014 | G3: 01-01-2026 | H3: Romania | P3: Deactivated | Q3: Physical SIM | T3: =IF($C3="","",IF($V3="","No digits at all - enter a phone number",IF(NOT(SUMPRODUCT(--ISNUMBER(--MID($V3,ROW(INDIRECT("1:"&LEN($V3))),1)))=LEN($V3)),"Digits only - no letters or symbols (+ ( ) - . and spaces are tolerated)",IF(LEN($V3)<8,"Too short - "&LEN($V3)&" digits (min 8)",IF(LEN($V3)>15,"Too long - "&LEN($V3)&" digits (max 15)",IF($H3="","WARNING: SIM_Country is empty - cannot check the country code",IF(ISNA(MATCH($H3,tblCountries[Name],0)),"WARNING: SIM_Country """&$H3&""" is not in tblCountries",IF(LEFT($V3,LEN(TEXT(INDEX(tblCountries[DialCode],MATCH($H3,tblCountries[Name],0)),"0")))<>TEXT(INDEX(tblCountries[DialCode],MATCH($H3,tblCountries[Name],0)),"0"),"Wrong country code - must start with +"&TEXT(INDEX(tblCountries[DialCode],MATCH($H3,tblCountries[Name],0)),"0")&" for "&$H3,"OK")))))))) -> OK | U3: 861234567890127 | V3: =IF($C3="","",IF(LEFT(SUBSTITUTE(SUBSTITUTE(SUBSTITUTE(SUBSTITUTE(SUBSTITUTE(SUBSTITUTE(SUBSTITUTE(TRIM($C3&""),"+","")," ",""),"-",""),"(",""),")",""),".",""),CHAR(160),""),2)="00",MID(SUBSTITUTE(SUBSTITUTE(SUBSTITUTE(SUBSTITUTE(SUBSTITUTE(SUBSTITUTE(SUBSTITUTE(TRIM($C3&""),"+","")," ",""),"-",""),"(",""),")",""),".",""),CHAR(160),""),3,255),SUBSTITUTE(SUBSTITUTE(SUBSTITUTE(SUBSTITUTE(SUBSTITUTE(SUBSTITUTE(SUBSTITUTE(TRIM($C3&""),"+","")," ",""),"-",""),"(",""),")",""),".",""),CHAR(160),""))) -> 40712345678 | W3: =IF($E3="","",IF(ISNUMBER($E3),"Stored as a NUMBER - every digit past the 15th is already lost. Format the column as Text and re-enter.",IF(NOT(SUMPRODUCT(--ISNUMBER(--MID(TRIM($E3&""),ROW(INDIRECT("1:"&LEN(TRIM($E3&"")))),1)))=LEN(TRIM($E3&""))),"Digits only - no +, -, spaces or any other character",IF(LEFT(TRIM($E3&""),2)<>"89","Must start with 89 (ITU-T E.118 telecom prefix)",IF(LEN(TRIM($E3&""))<18,"Too short - "&LEN(TRIM($E3&""))&" digits (min 18)",IF(LEN(TRIM($E3&""))>22,"Too long - "&LEN(TRIM($E3&""))&" digits (max 22)",IF(NOT(MOD(SUMPRODUCT(MID(TRIM($E3&""),ROW(INDIRECT("1:"&LEN(TRIM($E3&"")))),1)*1*(1+MOD(LEN(TRIM($E3&""))-ROW(INDIRECT("1:"&LEN(TRIM($E3&"")))),2))-MOD(LEN(TRIM($E3&""))-ROW(INDIRECT("1:"&LEN(TRIM($E3&"")))),2)*9*(MID(TRIM($E3&""),ROW(INDIRECT("1:"&LEN(TRIM($E3&"")))),1)*1*2>9)),10)=0),"WARNING: Luhn check digit does not match - likely a typo or a transposition","OK"))))))) -> OK | X3: =IF($U3="","",IF(NOT(SUMPRODUCT(--ISNUMBER(--MID(TRIM($U3&""),ROW(INDIRECT("1:"&LEN(TRIM($U3&"")))),1)))=LEN(TRIM($U3&""))),"Digits only - no +, -, spaces or any other character",IF(LEN(TRIM($U3&""))<>15,"Must be exactly 15 digits - this one has "&LEN(TRIM($U3&"")),IF(NOT(MOD(SUMPRODUCT(MID(TRIM($U3&""),ROW(INDIRECT("1:"&LEN(TRIM($U3&"")))),1)*1*(1+MOD(LEN(TRIM($U3&""))-ROW(INDIRECT("1:"&LEN(TRIM($U3&"")))),2))-MOD(LEN(TRIM($U3&""))-ROW(INDIRECT("1:"&LEN(TRIM($U3&"")))),2)*9*(MID(TRIM($U3&""),ROW(INDIRECT("1:"&LEN(TRIM($U3&"")))),1)*1*2>9)),10)=0),"WARNING: Luhn check digit does not match - likely a typo or a transposition","OK")))) -> OK | Y3: =IF($G3="","",IF(ISNUMBER($G3),IF(OR($G3<DATE(2000,1,1),$G3>TODAY()+730),"WARNING: real date, but outside 2000-01-01 .. today+2y - check the day/month order","OK"),IF(LEN(TRIM($G3&""))<>10,"Must be dd-mm-yyyy - 10 characters, this one has "&LEN(TRIM($G3&"")),IF(AND(NOT(ISERROR(FIND(MID(TRIM($G3&""),5,1),"-/."))),NOT(ISERROR(FIND(MID(TRIM($G3&""),8,1),"-/."))),SUMPRODUCT(--ISNUMBER(--MID(LEFT(TRIM($G3&""),4),ROW(INDIRECT("1:"&LEN(LEFT(TRIM($G3&""),4)))),1)))=LEN(LEFT(TRIM($G3&""),4))),"Looks like yyyy-mm-dd - StartDate must put the DAY first: dd-mm-yyyy",IF(OR(MID(TRIM($G3&""),3,1)<>MID(TRIM($G3&""),6,1),ISERROR(FIND(MID(TRIM($G3&""),3,1),"-/."))),"Separators must be in positions 3 and 6, matching, and be - or / or .",IF(NOT(AND(SUMPRODUCT(--ISNUMBER(--MID(LEFT(TRIM($G3&""),2),ROW(INDIRECT("1:"&LEN(LEFT(TRIM($G3&""),2)))),1)))=LEN(LEFT(TRIM($G3&""),2)),SUMPRODUCT(--ISNUMBER(--MID(MID(TRIM($G3&""),4,2),ROW(INDIRECT("1:"&LEN(MID(TRIM($G3&""),4,2)))),1)))=LEN(MID(TRIM($G3&""),4,2)),SUMPRODUCT(--ISNUMBER(--MID(RIGHT(TRIM($G3&""),4),ROW(INDIRECT("1:"&LEN(RIGHT(TRIM($G3&""),4)))),1)))=LEN(RIGHT(TRIM($G3&""),4)))),"Day, month and year must all be digits",IF(OR(LEFT(TRIM($G3&""),2)*1<1,LEFT(TRIM($G3&""),2)*1>31),"Day out of range - dd-mm-yyyy puts the DAY first",IF(OR(MID(TRIM($G3&""),4,2)*1<1,MID(TRIM($G3&""),4,2)*1>12),"Month out of range - dd-mm-yyyy puts the MONTH second",IF(OR(RIGHT(TRIM($G3&""),4)*1<2000,RIGHT(TRIM($G3&""),4)*1>2100),"Year out of range (2000-2100)",IF(DAY(DATE(RIGHT(TRIM($G3&""),4)*1,MID(TRIM($G3&""),4,2)*1,LEFT(TRIM($G3&""),2)*1))<>LEFT(TRIM($G3&""),2)*1,"Not a real calendar date (e.g. 31-02 or 30-02)","OK")))))))))) -> OK | Z3: =IF($P3="","",IF(SUMPRODUCT(--EXACT($P3,Config!$G$2:$G$4))>0,"OK",IF(NOT(ISNA(MATCH($P3,Config!$G$2:$G$4,0))),"WARNING: wrong capitalisation - should be """&INDEX(Config!$G$2:$G$4,MATCH($P3,Config!$G$2:$G$4,0))&""" exactly","Must be one of: Active, Deactivated, Suspended"))) -> OK | AA3: =IF($Q3="","",IF(SUMPRODUCT(--EXACT($Q3,Config!$H$2:$H$3))>0,"OK",IF(NOT(ISNA(MATCH($Q3,Config!$H$2:$H$3,0))),"WARNING: wrong capitalisation - should be """&INDEX(Config!$H$2:$H$3,MATCH($Q3,Config!$H$2:$H$3,0))&""" exactly","Must be one of: eSIM, Physical SIM"))) -> OK | AB3: =IF(IF(OR($T3="",$T3="OK"),"","PhoneNr: "&$T3&" // ")&IF(OR($W3="",$W3="OK"),"","ICC_ID: "&$W3&" // ")&IF(OR($Y3="",$Y3="OK"),"","StartDate: "&$Y3&" // ")&IF(OR($Z3="",$Z3="OK"),"","Status: "&$Z3&" // ")&IF(OR($AA3="",$AA3="OK"),"","SIM Type: "&$AA3&" // ")&IF(OR($X3="",$X3="OK"),"","IMEI: "&$X3&" // ")="","OK",LEFT(IF(OR($T3="",$T3="OK"),"","PhoneNr: "&$T3&" // ")&IF(OR($W3="",$W3="OK"),"","ICC_ID: "&$W3&" // ")&IF(OR($Y3="",$Y3="OK"),"","StartDate: "&$Y3&" // ")&IF(OR($Z3="",$Z3="OK"),"","Status: "&$Z3&" // ")&IF(OR($AA3="",$AA3="OK"),"","SIM Type: "&$AA3&" // ")&IF(OR($X3="",$X3="OK"),"","IMEI: "&$X3&" // "),LEN(IF(OR($T3="",$T3="OK"),"","PhoneNr: "&$T3&" // ")&IF(OR($W3="",$W3="OK"),"","ICC_ID: "&$W3&" // ")&IF(OR($Y3="",$Y3="OK"),"","StartDate: "&$Y3&" // ")&IF(OR($Z3="",$Z3="OK"),"","Status: "&$Z3&" // ")&IF(OR($AA3="",$AA3="OK"),"","SIM Type: "&$AA3&" // ")&IF(OR($X3="",$X3="OK"),"","IMEI: "&$X3&" // "))-6)) -> OK | AD3: PhoneNr: valid, bare digits
A4: Elena | B4: Dumitru | C4: 0712345678 | E4: 89352012345678901236 | G4: 28-02-2026 | H4: Romania | P4: Active | Q4: eSIM | T4: =IF($C4="","",IF($V4="","No digits at all - enter a phone number",IF(NOT(SUMPRODUCT(--ISNUMBER(--MID($V4,ROW(INDIRECT("1:"&LEN($V4))),1)))=LEN($V4)),"Digits only - no letters or symbols (+ ( ) - . and spaces are tolerated)",IF(LEN($V4)<8,"Too short - "&LEN($V4)&" digits (min 8)",IF(LEN($V4)>15,"Too long - "&LEN($V4)&" digits (max 15)",IF($H4="","WARNING: SIM_Country is empty - cannot check the country code",IF(ISNA(MATCH($H4,tblCountries[Name],0)),"WARNING: SIM_Country """&$H4&""" is not in tblCountries",IF(LEFT($V4,LEN(TEXT(INDEX(tblCountries[DialCode],MATCH($H4,tblCountries[Name],0)),"0")))<>TEXT(INDEX(tblCountries[DialCode],MATCH($H4,tblCountries[Name],0)),"0"),"Wrong country code - must start with +"&TEXT(INDEX(tblCountries[DialCode],MATCH($H4,tblCountries[Name],0)),"0")&" for "&$H4,"OK")))))))) -> Wrong country code - must start with +40 for Romania | U4: 352099001760897 | V4: =IF($C4="","",IF(LEFT(SUBSTITUTE(SUBSTITUTE(SUBSTITUTE(SUBSTITUTE(SUBSTITUTE(SUBSTITUTE(SUBSTITUTE(TRIM($C4&""),"+","")," ",""),"-",""),"(",""),")",""),".",""),CHAR(160),""),2)="00",MID(SUBSTITUTE(SUBSTITUTE(SUBSTITUTE(SUBSTITUTE(SUBSTITUTE(SUBSTITUTE(SUBSTITUTE(TRIM($C4&""),"+","")," ",""),"-",""),"(",""),")",""),".",""),CHAR(160),""),3,255),SUBSTITUTE(SUBSTITUTE(SUBSTITUTE(SUBSTITUTE(SUBSTITUTE(SUBSTITUTE(SUBSTITUTE(TRIM($C4&""),"+","")," ",""),"-",""),"(",""),")",""),".",""),CHAR(160),""))) -> 0712345678 | W4: =IF($E4="","",IF(ISNUMBER($E4),"Stored as a NUMBER - every digit past the 15th is already lost. Format the column as Text and re-enter.",IF(NOT(SUMPRODUCT(--ISNUMBER(--MID(TRIM($E4&""),ROW(INDIRECT("1:"&LEN(TRIM($E4&"")))),1)))=LEN(TRIM($E4&""))),"Digits only - no +, -, spaces or any other character",IF(LEFT(TRIM($E4&""),2)<>"89","Must start with 89 (ITU-T E.118 telecom prefix)",IF(LEN(TRIM($E4&""))<18,"Too short - "&LEN(TRIM($E4&""))&" digits (min 18)",IF(LEN(TRIM($E4&""))>22,"Too long - "&LEN(TRIM($E4&""))&" digits (max 22)",IF(NOT(MOD(SUMPRODUCT(MID(TRIM($E4&""),ROW(INDIRECT("1:"&LEN(TRIM($E4&"")))),1)*1*(1+MOD(LEN(TRIM($E4&""))-ROW(INDIRECT("1:"&LEN(TRIM($E4&"")))),2))-MOD(LEN(TRIM($E4&""))-ROW(INDIRECT("1:"&LEN(TRIM($E4&"")))),2)*9*(MID(TRIM($E4&""),ROW(INDIRECT("1:"&LEN(TRIM($E4&"")))),1)*1*2>9)),10)=0),"WARNING: Luhn check digit does not match - likely a typo or a transposition","OK"))))))) -> OK | X4: =IF($U4="","",IF(NOT(SUMPRODUCT(--ISNUMBER(--MID(TRIM($U4&""),ROW(INDIRECT("1:"&LEN(TRIM($U4&"")))),1)))=LEN(TRIM($U4&""))),"Digits only - no +, -, spaces or any other character",IF(LEN(TRIM($U4&""))<>15,"Must be exactly 15 digits - this one has "&LEN(TRIM($U4&"")),IF(NOT(MOD(SUMPRODUCT(MID(TRIM($U4&""),ROW(INDIRECT("1:"&LEN(TRIM($U4&"")))),1)*1*(1+MOD(LEN(TRIM($U4&""))-ROW(INDIRECT("1:"&LEN(TRIM($U4&"")))),2))-MOD(LEN(TRIM($U4&""))-ROW(INDIRECT("1:"&LEN(TRIM($U4&"")))),2)*9*(MID(TRIM($U4&""),ROW(INDIRECT("1:"&LEN(TRIM($U4&"")))),1)*1*2>9)),10)=0),"WARNING: Luhn check digit does not match - likely a typo or a transposition","OK")))) -> OK | Y4: =IF($G4="","",IF(ISNUMBER($G4),IF(OR($G4<DATE(2000,1,1),$G4>TODAY()+730),"WARNING: real date, but outside 2000-01-01 .. today+2y - check the day/month order","OK"),IF(LEN(TRIM($G4&""))<>10,"Must be dd-mm-yyyy - 10 characters, this one has "&LEN(TRIM($G4&"")),IF(AND(NOT(ISERROR(FIND(MID(TRIM($G4&""),5,1),"-/."))),NOT(ISERROR(FIND(MID(TRIM($G4&""),8,1),"-/."))),SUMPRODUCT(--ISNUMBER(--MID(LEFT(TRIM($G4&""),4),ROW(INDIRECT("1:"&LEN(LEFT(TRIM($G4&""),4)))),1)))=LEN(LEFT(TRIM($G4&""),4))),"Looks like yyyy-mm-dd - StartDate must put the DAY first: dd-mm-yyyy",IF(OR(MID(TRIM($G4&""),3,1)<>MID(TRIM($G4&""),6,1),ISERROR(FIND(MID(TRIM($G4&""),3,1),"-/."))),"Separators must be in positions 3 and 6, matching, and be - or / or .",IF(NOT(AND(SUMPRODUCT(--ISNUMBER(--MID(LEFT(TRIM($G4&""),2),ROW(INDIRECT("1:"&LEN(LEFT(TRIM($G4&""),2)))),1)))=LEN(LEFT(TRIM($G4&""),2)),SUMPRODUCT(--ISNUMBER(--MID(MID(TRIM($G4&""),4,2),ROW(INDIRECT("1:"&LEN(MID(TRIM($G4&""),4,2)))),1)))=LEN(MID(TRIM($G4&""),4,2)),SUMPRODUCT(--ISNUMBER(--MID(RIGHT(TRIM($G4&""),4),ROW(INDIRECT("1:"&LEN(RIGHT(TRIM($G4&""),4)))),1)))=LEN(RIGHT(TRIM($G4&""),4)))),"Day, month and year must all be digits",IF(OR(LEFT(TRIM($G4&""),2)*1<1,LEFT(TRIM($G4&""),2)*1>31),"Day out of range - dd-mm-yyyy puts the DAY first",IF(OR(MID(TRIM($G4&""),4,2)*1<1,MID(TRIM($G4&""),4,2)*1>12),"Month out of range - dd-mm-yyyy puts the MONTH second",IF(OR(RIGHT(TRIM($G4&""),4)*1<2000,RIGHT(TRIM($G4&""),4)*1>2100),"Year out of range (2000-2100)",IF(DAY(DATE(RIGHT(TRIM($G4&""),4)*1,MID(TRIM($G4&""),4,2)*1,LEFT(TRIM($G4&""),2)*1))<>LEFT(TRIM($G4&""),2)*1,"Not a real calendar date (e.g. 31-02 or 30-02)","OK")))))))))) -> OK | Z4: =IF($P4="","",IF(SUMPRODUCT(--EXACT($P4,Config!$G$2:$G$4))>0,"OK",IF(NOT(ISNA(MATCH($P4,Config!$G$2:$G$4,0))),"WARNING: wrong capitalisation - should be """&INDEX(Config!$G$2:$G$4,MATCH($P4,Config!$G$2:$G$4,0))&""" exactly","Must be one of: Active, Deactivated, Suspended"))) -> OK | AA4: =IF($Q4="","",IF(SUMPRODUCT(--EXACT($Q4,Config!$H$2:$H$3))>0,"OK",IF(NOT(ISNA(MATCH($Q4,Config!$H$2:$H$3,0))),"WARNING: wrong capitalisation - should be """&INDEX(Config!$H$2:$H$3,MATCH($Q4,Config!$H$2:$H$3,0))&""" exactly","Must be one of: eSIM, Physical SIM"))) -> OK | AB4: =IF(IF(OR($T4="",$T4="OK"),"","PhoneNr: "&$T4&" // ")&IF(OR($W4="",$W4="OK"),"","ICC_ID: "&$W4&" // ")&IF(OR($Y4="",$Y4="OK"),"","StartDate: "&$Y4&" // ")&IF(OR($Z4="",$Z4="OK"),"","Status: "&$Z4&" // ")&IF(OR($AA4="",$AA4="OK"),"","SIM Type: "&$AA4&" // ")&IF(OR($X4="",$X4="OK"),"","IMEI: "&$X4&" // ")="","OK",LEFT(IF(OR($T4="",$T4="OK"),"","PhoneNr: "&$T4&" // ")&IF(OR($W4="",$W4="OK"),"","ICC_ID: "&$W4&" // ")&IF(OR($Y4="",$Y4="OK"),"","StartDate: "&$Y4&" // ")&IF(OR($Z4="",$Z4="OK"),"","Status: "&$Z4&" // ")&IF(OR($AA4="",$AA4="OK"),"","SIM Type: "&$AA4&" // ")&IF(OR($X4="",$X4="OK"),"","IMEI: "&$X4&" // "),LEN(IF(OR($T4="",$T4="OK"),"","PhoneNr: "&$T4&" // ")&IF(OR($W4="",$W4="OK"),"","ICC_ID: "&$W4&" // ")&IF(OR($Y4="",$Y4="OK"),"","StartDate: "&$Y4&" // ")&IF(OR($Z4="",$Z4="OK"),"","Status: "&$Z4&" // ")&IF(OR($AA4="",$AA4="OK"),"","SIM Type: "&$AA4&" // ")&IF(OR($X4="",$X4="OK"),"","IMEI: "&$X4&" // "))-6)) -> PhoneNr: Wrong country code - must start with +40 for Romania | AD4: PhoneNr: national format, no country code
A5: Lukas | B5: Muller | C5: +49 151 1234 5678 | E5: 8935201234567890123451 | G5: 10-06-2025 | H5: Germany | P5: Suspended | Q5: Physical SIM | T5: =IF($C5="","",IF($V5="","No digits at all - enter a phone number",IF(NOT(SUMPRODUCT(--ISNUMBER(--MID($V5,ROW(INDIRECT("1:"&LEN($V5))),1)))=LEN($V5)),"Digits only - no letters or symbols (+ ( ) - . and spaces are tolerated)",IF(LEN($V5)<8,"Too short - "&LEN($V5)&" digits (min 8)",IF(LEN($V5)>15,"Too long - "&LEN($V5)&" digits (max 15)",IF($H5="","WARNING: SIM_Country is empty - cannot check the country code",IF(ISNA(MATCH($H5,tblCountries[Name],0)),"WARNING: SIM_Country """&$H5&""" is not in tblCountries",IF(LEFT($V5,LEN(TEXT(INDEX(tblCountries[DialCode],MATCH($H5,tblCountries[Name],0)),"0")))<>TEXT(INDEX(tblCountries[DialCode],MATCH($H5,tblCountries[Name],0)),"0"),"Wrong country code - must start with +"&TEXT(INDEX(tblCountries[DialCode],MATCH($H5,tblCountries[Name],0)),"0")&" for "&$H5,"OK")))))))) -> OK | U5: 861234567890127 | V5: =IF($C5="","",IF(LEFT(SUBSTITUTE(SUBSTITUTE(SUBSTITUTE(SUBSTITUTE(SUBSTITUTE(SUBSTITUTE(SUBSTITUTE(TRIM($C5&""),"+","")," ",""),"-",""),"(",""),")",""),".",""),CHAR(160),""),2)="00",MID(SUBSTITUTE(SUBSTITUTE(SUBSTITUTE(SUBSTITUTE(SUBSTITUTE(SUBSTITUTE(SUBSTITUTE(TRIM($C5&""),"+","")," ",""),"-",""),"(",""),")",""),".",""),CHAR(160),""),3,255),SUBSTITUTE(SUBSTITUTE(SUBSTITUTE(SUBSTITUTE(SUBSTITUTE(SUBSTITUTE(SUBSTITUTE(TRIM($C5&""),"+","")," ",""),"-",""),"(",""),")",""),".",""),CHAR(160),""))) -> 4915112345678 | W5: =IF($E5="","",IF(ISNUMBER($E5),"Stored as a NUMBER - every digit past the 15th is already lost. Format the column as Text and re-enter.",IF(NOT(SUMPRODUCT(--ISNUMBER(--MID(TRIM($E5&""),ROW(INDIRECT("1:"&LEN(TRIM($E5&"")))),1)))=LEN(TRIM($E5&""))),"Digits only - no +, -, spaces or any other character",IF(LEFT(TRIM($E5&""),2)<>"89","Must start with 89 (ITU-T E.118 telecom prefix)",IF(LEN(TRIM($E5&""))<18,"Too short - "&LEN(TRIM($E5&""))&" digits (min 18)",IF(LEN(TRIM($E5&""))>22,"Too long - "&LEN(TRIM($E5&""))&" digits (max 22)",IF(NOT(MOD(SUMPRODUCT(MID(TRIM($E5&""),ROW(INDIRECT("1:"&LEN(TRIM($E5&"")))),1)*1*(1+MOD(LEN(TRIM($E5&""))-ROW(INDIRECT("1:"&LEN(TRIM($E5&"")))),2))-MOD(LEN(TRIM($E5&""))-ROW(INDIRECT("1:"&LEN(TRIM($E5&"")))),2)*9*(MID(TRIM($E5&""),ROW(INDIRECT("1:"&LEN(TRIM($E5&"")))),1)*1*2>9)),10)=0),"WARNING: Luhn check digit does not match - likely a typo or a transposition","OK"))))))) -> OK | X5: =IF($U5="","",IF(NOT(SUMPRODUCT(--ISNUMBER(--MID(TRIM($U5&""),ROW(INDIRECT("1:"&LEN(TRIM($U5&"")))),1)))=LEN(TRIM($U5&""))),"Digits only - no +, -, spaces or any other character",IF(LEN(TRIM($U5&""))<>15,"Must be exactly 15 digits - this one has "&LEN(TRIM($U5&"")),IF(NOT(MOD(SUMPRODUCT(MID(TRIM($U5&""),ROW(INDIRECT("1:"&LEN(TRIM($U5&"")))),1)*1*(1+MOD(LEN(TRIM($U5&""))-ROW(INDIRECT("1:"&LEN(TRIM($U5&"")))),2))-MOD(LEN(TRIM($U5&""))-ROW(INDIRECT("1:"&LEN(TRIM($U5&"")))),2)*9*(MID(TRIM($U5&""),ROW(INDIRECT("1:"&LEN(TRIM($U5&"")))),1)*1*2>9)),10)=0),"WARNING: Luhn check digit does not match - likely a typo or a transposition","OK")))) -> OK | Y5: =IF($G5="","",IF(ISNUMBER($G5),IF(OR($G5<DATE(2000,1,1),$G5>TODAY()+730),"WARNING: real date, but outside 2000-01-01 .. today+2y - check the day/month order","OK"),IF(LEN(TRIM($G5&""))<>10,"Must be dd-mm-yyyy - 10 characters, this one has "&LEN(TRIM($G5&"")),IF(AND(NOT(ISERROR(FIND(MID(TRIM($G5&""),5,1),"-/."))),NOT(ISERROR(FIND(MID(TRIM($G5&""),8,1),"-/."))),SUMPRODUCT(--ISNUMBER(--MID(LEFT(TRIM($G5&""),4),ROW(INDIRECT("1:"&LEN(LEFT(TRIM($G5&""),4)))),1)))=LEN(LEFT(TRIM($G5&""),4))),"Looks like yyyy-mm-dd - StartDate must put the DAY first: dd-mm-yyyy",IF(OR(MID(TRIM($G5&""),3,1)<>MID(TRIM($G5&""),6,1),ISERROR(FIND(MID(TRIM($G5&""),3,1),"-/."))),"Separators must be in positions 3 and 6, matching, and be - or / or .",IF(NOT(AND(SUMPRODUCT(--ISNUMBER(--MID(LEFT(TRIM($G5&""),2),ROW(INDIRECT("1:"&LEN(LEFT(TRIM($G5&""),2)))),1)))=LEN(LEFT(TRIM($G5&""),2)),SUMPRODUCT(--ISNUMBER(--MID(MID(TRIM($G5&""),4,2),ROW(INDIRECT("1:"&LEN(MID(TRIM($G5&""),4,2)))),1)))=LEN(MID(TRIM($G5&""),4,2)),SUMPRODUCT(--ISNUMBER(--MID(RIGHT(TRIM($G5&""),4),ROW(INDIRECT("1:"&LEN(RIGHT(TRIM($G5&""),4)))),1)))=LEN(RIGHT(TRIM($G5&""),4)))),"Day, month and year must all be digits",IF(OR(LEFT(TRIM($G5&""),2)*1<1,LEFT(TRIM($G5&""),2)*1>31),"Day out of range - dd-mm-yyyy puts the DAY first",IF(OR(MID(TRIM($G5&""),4,2)*1<1,MID(TRIM($G5&""),4,2)*1>12),"Month out of range - dd-mm-yyyy puts the MONTH second",IF(OR(RIGHT(TRIM($G5&""),4)*1<2000,RIGHT(TRIM($G5&""),4)*1>2100),"Year out of range (2000-2100)",IF(DAY(DATE(RIGHT(TRIM($G5&""),4)*1,MID(TRIM($G5&""),4,2)*1,LEFT(TRIM($G5&""),2)*1))<>LEFT(TRIM($G5&""),2)*1,"Not a real calendar date (e.g. 31-02 or 30-02)","OK")))))))))) -> OK | Z5: =IF($P5="","",IF(SUMPRODUCT(--EXACT($P5,Config!$G$2:$G$4))>0,"OK",IF(NOT(ISNA(MATCH($P5,Config!$G$2:$G$4,0))),"WARNING: wrong capitalisation - should be """&INDEX(Config!$G$2:$G$4,MATCH($P5,Config!$G$2:$G$4,0))&""" exactly","Must be one of: Active, Deactivated, Suspended"))) -> OK | AA5: =IF($Q5="","",IF(SUMPRODUCT(--EXACT($Q5,Config!$H$2:$H$3))>0,"OK",IF(NOT(ISNA(MATCH($Q5,Config!$H$2:$H$3,0))),"WARNING: wrong capitalisation - should be """&INDEX(Config!$H$2:$H$3,MATCH($Q5,Config!$H$2:$H$3,0))&""" exactly","Must be one of: eSIM, Physical SIM"))) -> OK | AB5: =IF(IF(OR($T5="",$T5="OK"),"","PhoneNr: "&$T5&" // ")&IF(OR($W5="",$W5="OK"),"","ICC_ID: "&$W5&" // ")&IF(OR($Y5="",$Y5="OK"),"","StartDate: "&$Y5&" // ")&IF(OR($Z5="",$Z5="OK"),"","Status: "&$Z5&" // ")&IF(OR($AA5="",$AA5="OK"),"","SIM Type: "&$AA5&" // ")&IF(OR($X5="",$X5="OK"),"","IMEI: "&$X5&" // ")="","OK",LEFT(IF(OR($T5="",$T5="OK"),"","PhoneNr: "&$T5&" // ")&IF(OR($W5="",$W5="OK"),"","ICC_ID: "&$W5&" // ")&IF(OR($Y5="",$Y5="OK"),"","StartDate: "&$Y5&" // ")&IF(OR($Z5="",$Z5="OK"),"","Status: "&$Z5&" // ")&IF(OR($AA5="",$AA5="OK"),"","SIM Type: "&$AA5&" // ")&IF(OR($X5="",$X5="OK"),"","IMEI: "&$X5&" // "),LEN(IF(OR($T5="",$T5="OK"),"","PhoneNr: "&$T5&" // ")&IF(OR($W5="",$W5="OK"),"","ICC_ID: "&$W5&" // ")&IF(OR($Y5="",$Y5="OK"),"","StartDate: "&$Y5&" // ")&IF(OR($Z5="",$Z5="OK"),"","Status: "&$Z5&" // ")&IF(OR($AA5="",$AA5="OK"),"","SIM Type: "&$AA5&" // ")&IF(OR($X5="",$X5="OK"),"","IMEI: "&$X5&" // "))-6)) -> OK | AD5: PhoneNr: valid, spaces stripped
A6: Claire | B6: Dubois | C6: 0033612345678 | E6: 8935201234567890125 | G6: 05-11-2025 | H6: France | P6: Active | Q6: eSIM | T6: =IF($C6="","",IF($V6="","No digits at all - enter a phone number",IF(NOT(SUMPRODUCT(--ISNUMBER(--MID($V6,ROW(INDIRECT("1:"&LEN($V6))),1)))=LEN($V6)),"Digits only - no letters or symbols (+ ( ) - . and spaces are tolerated)",IF(LEN($V6)<8,"Too short - "&LEN($V6)&" digits (min 8)",IF(LEN($V6)>15,"Too long - "&LEN($V6)&" digits (max 15)",IF($H6="","WARNING: SIM_Country is empty - cannot check the country code",IF(ISNA(MATCH($H6,tblCountries[Name],0)),"WARNING: SIM_Country """&$H6&""" is not in tblCountries",IF(LEFT($V6,LEN(TEXT(INDEX(tblCountries[DialCode],MATCH($H6,tblCountries[Name],0)),"0")))<>TEXT(INDEX(tblCountries[DialCode],MATCH($H6,tblCountries[Name],0)),"0"),"Wrong country code - must start with +"&TEXT(INDEX(tblCountries[DialCode],MATCH($H6,tblCountries[Name],0)),"0")&" for "&$H6,"OK")))))))) -> OK | U6: 352099001760897 | V6: =IF($C6="","",IF(LEFT(SUBSTITUTE(SUBSTITUTE(SUBSTITUTE(SUBSTITUTE(SUBSTITUTE(SUBSTITUTE(SUBSTITUTE(TRIM($C6&""),"+","")," ",""),"-",""),"(",""),")",""),".",""),CHAR(160),""),2)="00",MID(SUBSTITUTE(SUBSTITUTE(SUBSTITUTE(SUBSTITUTE(SUBSTITUTE(SUBSTITUTE(SUBSTITUTE(TRIM($C6&""),"+","")," ",""),"-",""),"(",""),")",""),".",""),CHAR(160),""),3,255),SUBSTITUTE(SUBSTITUTE(SUBSTITUTE(SUBSTITUTE(SUBSTITUTE(SUBSTITUTE(SUBSTITUTE(TRIM($C6&""),"+","")," ",""),"-",""),"(",""),")",""),".",""),CHAR(160),""))) -> 33612345678 | W6: =IF($E6="","",IF(ISNUMBER($E6),"Stored as a NUMBER - every digit past the 15th is already lost. Format the column as Text and re-enter.",IF(NOT(SUMPRODUCT(--ISNUMBER(--MID(TRIM($E6&""),ROW(INDIRECT("1:"&LEN(TRIM($E6&"")))),1)))=LEN(TRIM($E6&""))),"Digits only - no +, -, spaces or any other character",IF(LEFT(TRIM($E6&""),2)<>"89","Must start with 89 (ITU-T E.118 telecom prefix)",IF(LEN(TRIM($E6&""))<18,"Too short - "&LEN(TRIM($E6&""))&" digits (min 18)",IF(LEN(TRIM($E6&""))>22,"Too long - "&LEN(TRIM($E6&""))&" digits (max 22)",IF(NOT(MOD(SUMPRODUCT(MID(TRIM($E6&""),ROW(INDIRECT("1:"&LEN(TRIM($E6&"")))),1)*1*(1+MOD(LEN(TRIM($E6&""))-ROW(INDIRECT("1:"&LEN(TRIM($E6&"")))),2))-MOD(LEN(TRIM($E6&""))-ROW(INDIRECT("1:"&LEN(TRIM($E6&"")))),2)*9*(MID(TRIM($E6&""),ROW(INDIRECT("1:"&LEN(TRIM($E6&"")))),1)*1*2>9)),10)=0),"WARNING: Luhn check digit does not match - likely a typo or a transposition","OK"))))))) -> OK | X6: =IF($U6="","",IF(NOT(SUMPRODUCT(--ISNUMBER(--MID(TRIM($U6&""),ROW(INDIRECT("1:"&LEN(TRIM($U6&"")))),1)))=LEN(TRIM($U6&""))),"Digits only - no +, -, spaces or any other character",IF(LEN(TRIM($U6&""))<>15,"Must be exactly 15 digits - this one has "&LEN(TRIM($U6&"")),IF(NOT(MOD(SUMPRODUCT(MID(TRIM($U6&""),ROW(INDIRECT("1:"&LEN(TRIM($U6&"")))),1)*1*(1+MOD(LEN(TRIM($U6&""))-ROW(INDIRECT("1:"&LEN(TRIM($U6&"")))),2))-MOD(LEN(TRIM($U6&""))-ROW(INDIRECT("1:"&LEN(TRIM($U6&"")))),2)*9*(MID(TRIM($U6&""),ROW(INDIRECT("1:"&LEN(TRIM($U6&"")))),1)*1*2>9)),10)=0),"WARNING: Luhn check digit does not match - likely a typo or a transposition","OK")))) -> OK | Y6: =IF($G6="","",IF(ISNUMBER($G6),IF(OR($G6<DATE(2000,1,1),$G6>TODAY()+730),"WARNING: real date, but outside 2000-01-01 .. today+2y - check the day/month order","OK"),IF(LEN(TRIM($G6&""))<>10,"Must be dd-mm-yyyy - 10 characters, this one has "&LEN(TRIM($G6&"")),IF(AND(NOT(ISERROR(FIND(MID(TRIM($G6&""),5,1),"-/."))),NOT(ISERROR(FIND(MID(TRIM($G6&""),8,1),"-/."))),SUMPRODUCT(--ISNUMBER(--MID(LEFT(TRIM($G6&""),4),ROW(INDIRECT("1:"&LEN(LEFT(TRIM($G6&""),4)))),1)))=LEN(LEFT(TRIM($G6&""),4))),"Looks like yyyy-mm-dd - StartDate must put the DAY first: dd-mm-yyyy",IF(OR(MID(TRIM($G6&""),3,1)<>MID(TRIM($G6&""),6,1),ISERROR(FIND(MID(TRIM($G6&""),3,1),"-/."))),"Separators must be in positions 3 and 6, matching, and be - or / or .",IF(NOT(AND(SUMPRODUCT(--ISNUMBER(--MID(LEFT(TRIM($G6&""),2),ROW(INDIRECT("1:"&LEN(LEFT(TRIM($G6&""),2)))),1)))=LEN(LEFT(TRIM($G6&""),2)),SUMPRODUCT(--ISNUMBER(--MID(MID(TRIM($G6&""),4,2),ROW(INDIRECT("1:"&LEN(MID(TRIM($G6&""),4,2)))),1)))=LEN(MID(TRIM($G6&""),4,2)),SUMPRODUCT(--ISNUMBER(--MID(RIGHT(TRIM($G6&""),4),ROW(INDIRECT("1:"&LEN(RIGHT(TRIM($G6&""),4)))),1)))=LEN(RIGHT(TRIM($G6&""),4)))),"Day, month and year must all be digits",IF(OR(LEFT(TRIM($G6&""),2)*1<1,LEFT(TRIM($G6&""),2)*1>31),"Day out of range - dd-mm-yyyy puts the DAY first",IF(OR(MID(TRIM($G6&""),4,2)*1<1,MID(TRIM($G6&""),4,2)*1>12),"Month out of range - dd-mm-yyyy puts the MONTH second",IF(OR(RIGHT(TRIM($G6&""),4)*1<2000,RIGHT(TRIM($G6&""),4)*1>2100),"Year out of range (2000-2100)",IF(DAY(DATE(RIGHT(TRIM($G6&""),4)*1,MID(TRIM($G6&""),4,2)*1,LEFT(TRIM($G6&""),2)*1))<>LEFT(TRIM($G6&""),2)*1,"Not a real calendar date (e.g. 31-02 or 30-02)","OK")))))))))) -> OK | Z6: =IF($P6="","",IF(SUMPRODUCT(--EXACT($P6,Config!$G$2:$G$4))>0,"OK",IF(NOT(ISNA(MATCH($P6,Config!$G$2:$G$4,0))),"WARNING: wrong capitalisation - should be """&INDEX(Config!$G$2:$G$4,MATCH($P6,Config!$G$2:$G$4,0))&""" exactly","Must be one of: Active, Deactivated, Suspended"))) -> OK | AA6: =IF($Q6="","",IF(SUMPRODUCT(--EXACT($Q6,Config!$H$2:$H$3))>0,"OK",IF(NOT(ISNA(MATCH($Q6,Config!$H$2:$H$3,0))),"WARNING: wrong capitalisation - should be """&INDEX(Config!$H$2:$H$3,MATCH($Q6,Config!$H$2:$H$3,0))&""" exactly","Must be one of: eSIM, Physical SIM"))) -> OK | AB6: =IF(IF(OR($T6="",$T6="OK"),"","PhoneNr: "&$T6&" // ")&IF(OR($W6="",$W6="OK"),"","ICC_ID: "&$W6&" // ")&IF(OR($Y6="",$Y6="OK"),"","StartDate: "&$Y6&" // ")&IF(OR($Z6="",$Z6="OK"),"","Status: "&$Z6&" // ")&IF(OR($AA6="",$AA6="OK"),"","SIM Type: "&$AA6&" // ")&IF(OR($X6="",$X6="OK"),"","IMEI: "&$X6&" // ")="","OK",LEFT(IF(OR($T6="",$T6="OK"),"","PhoneNr: "&$T6&" // ")&IF(OR($W6="",$W6="OK"),"","ICC_ID: "&$W6&" // ")&IF(OR($Y6="",$Y6="OK"),"","StartDate: "&$Y6&" // ")&IF(OR($Z6="",$Z6="OK"),"","Status: "&$Z6&" // ")&IF(OR($AA6="",$AA6="OK"),"","SIM Type: "&$AA6&" // ")&IF(OR($X6="",$X6="OK"),"","IMEI: "&$X6&" // "),LEN(IF(OR($T6="",$T6="OK"),"","PhoneNr: "&$T6&" // ")&IF(OR($W6="",$W6="OK"),"","ICC_ID: "&$W6&" // ")&IF(OR($Y6="",$Y6="OK"),"","StartDate: "&$Y6&" // ")&IF(OR($Z6="",$Z6="OK"),"","Status: "&$Z6&" // ")&IF(OR($AA6="",$AA6="OK"),"","SIM Type: "&$AA6&" // ")&IF(OR($X6="",$X6="OK"),"","IMEI: "&$X6&" // "))-6)) -> OK | AD6: PhoneNr: valid, 00 prefix converted
A7: Sven | B7: Jansen | C7: +31-6-1234-5678 | E7: 8935201234567890125 | G7: 30-04-2026 | H7: Netherlands | P7: Active | Q7: Physical SIM | T7: =IF($C7="","",IF($V7="","No digits at all - enter a phone number",IF(NOT(SUMPRODUCT(--ISNUMBER(--MID($V7,ROW(INDIRECT("1:"&LEN($V7))),1)))=LEN($V7)),"Digits only - no letters or symbols (+ ( ) - . and spaces are tolerated)",IF(LEN($V7)<8,"Too short - "&LEN($V7)&" digits (min 8)",IF(LEN($V7)>15,"Too long - "&LEN($V7)&" digits (max 15)",IF($H7="","WARNING: SIM_Country is empty - cannot check the country code",IF(ISNA(MATCH($H7,tblCountries[Name],0)),"WARNING: SIM_Country """&$H7&""" is not in tblCountries",IF(LEFT($V7,LEN(TEXT(INDEX(tblCountries[DialCode],MATCH($H7,tblCountries[Name],0)),"0")))<>TEXT(INDEX(tblCountries[DialCode],MATCH($H7,tblCountries[Name],0)),"0"),"Wrong country code - must start with +"&TEXT(INDEX(tblCountries[DialCode],MATCH($H7,tblCountries[Name],0)),"0")&" for "&$H7,"OK")))))))) -> OK | U7: 861234567890127 | V7: =IF($C7="","",IF(LEFT(SUBSTITUTE(SUBSTITUTE(SUBSTITUTE(SUBSTITUTE(SUBSTITUTE(SUBSTITUTE(SUBSTITUTE(TRIM($C7&""),"+","")," ",""),"-",""),"(",""),")",""),".",""),CHAR(160),""),2)="00",MID(SUBSTITUTE(SUBSTITUTE(SUBSTITUTE(SUBSTITUTE(SUBSTITUTE(SUBSTITUTE(SUBSTITUTE(TRIM($C7&""),"+","")," ",""),"-",""),"(",""),")",""),".",""),CHAR(160),""),3,255),SUBSTITUTE(SUBSTITUTE(SUBSTITUTE(SUBSTITUTE(SUBSTITUTE(SUBSTITUTE(SUBSTITUTE(TRIM($C7&""),"+","")," ",""),"-",""),"(",""),")",""),".",""),CHAR(160),""))) -> 31612345678 | W7: =IF($E7="","",IF(ISNUMBER($E7),"Stored as a NUMBER - every digit past the 15th is already lost. Format the column as Text and re-enter.",IF(NOT(SUMPRODUCT(--ISNUMBER(--MID(TRIM($E7&""),ROW(INDIRECT("1:"&LEN(TRIM($E7&"")))),1)))=LEN(TRIM($E7&""))),"Digits only - no +, -, spaces or any other character",IF(LEFT(TRIM($E7&""),2)<>"89","Must start with 89 (ITU-T E.118 telecom prefix)",IF(LEN(TRIM($E7&""))<18,"Too short - "&LEN(TRIM($E7&""))&" digits (min 18)",IF(LEN(TRIM($E7&""))>22,"Too long - "&LEN(TRIM($E7&""))&" digits (max 22)",IF(NOT(MOD(SUMPRODUCT(MID(TRIM($E7&""),ROW(INDIRECT("1:"&LEN(TRIM($E7&"")))),1)*1*(1+MOD(LEN(TRIM($E7&""))-ROW(INDIRECT("1:"&LEN(TRIM($E7&"")))),2))-MOD(LEN(TRIM($E7&""))-ROW(INDIRECT("1:"&LEN(TRIM($E7&"")))),2)*9*(MID(TRIM($E7&""),ROW(INDIRECT("1:"&LEN(TRIM($E7&"")))),1)*1*2>9)),10)=0),"WARNING: Luhn check digit does not match - likely a typo or a transposition","OK"))))))) -> OK | X7: =IF($U7="","",IF(NOT(SUMPRODUCT(--ISNUMBER(--MID(TRIM($U7&""),ROW(INDIRECT("1:"&LEN(TRIM($U7&"")))),1)))=LEN(TRIM($U7&""))),"Digits only - no +, -, spaces or any other character",IF(LEN(TRIM($U7&""))<>15,"Must be exactly 15 digits - this one has "&LEN(TRIM($U7&"")),IF(NOT(MOD(SUMPRODUCT(MID(TRIM($U7&""),ROW(INDIRECT("1:"&LEN(TRIM($U7&"")))),1)*1*(1+MOD(LEN(TRIM($U7&""))-ROW(INDIRECT("1:"&LEN(TRIM($U7&"")))),2))-MOD(LEN(TRIM($U7&""))-ROW(INDIRECT("1:"&LEN(TRIM($U7&"")))),2)*9*(MID(TRIM($U7&""),ROW(INDIRECT("1:"&LEN(TRIM($U7&"")))),1)*1*2>9)),10)=0),"WARNING: Luhn check digit does not match - likely a typo or a transposition","OK")))) -> OK | Y7: =IF($G7="","",IF(ISNUMBER($G7),IF(OR($G7<DATE(2000,1,1),$G7>TODAY()+730),"WARNING: real date, but outside 2000-01-01 .. today+2y - check the day/month order","OK"),IF(LEN(TRIM($G7&""))<>10,"Must be dd-mm-yyyy - 10 characters, this one has "&LEN(TRIM($G7&"")),IF(AND(NOT(ISERROR(FIND(MID(TRIM($G7&""),5,1),"-/."))),NOT(ISERROR(FIND(MID(TRIM($G7&""),8,1),"-/."))),SUMPRODUCT(--ISNUMBER(--MID(LEFT(TRIM($G7&""),4),ROW(INDIRECT("1:"&LEN(LEFT(TRIM($G7&""),4)))),1)))=LEN(LEFT(TRIM($G7&""),4))),"Looks like yyyy-mm-dd - StartDate must put the DAY first: dd-mm-yyyy",IF(OR(MID(TRIM($G7&""),3,1)<>MID(TRIM($G7&""),6,1),ISERROR(FIND(MID(TRIM($G7&""),3,1),"-/."))),"Separators must be in positions 3 and 6, matching, and be - or / or .",IF(NOT(AND(SUMPRODUCT(--ISNUMBER(--MID(LEFT(TRIM($G7&""),2),ROW(INDIRECT("1:"&LEN(LEFT(TRIM($G7&""),2)))),1)))=LEN(LEFT(TRIM($G7&""),2)),SUMPRODUCT(--ISNUMBER(--MID(MID(TRIM($G7&""),4,2),ROW(INDIRECT("1:"&LEN(MID(TRIM($G7&""),4,2)))),1)))=LEN(MID(TRIM($G7&""),4,2)),SUMPRODUCT(--ISNUMBER(--MID(RIGHT(TRIM($G7&""),4),ROW(INDIRECT("1:"&LEN(RIGHT(TRIM($G7&""),4)))),1)))=LEN(RIGHT(TRIM($G7&""),4)))),"Day, month and year must all be digits",IF(OR(LEFT(TRIM($G7&""),2)*1<1,LEFT(TRIM($G7&""),2)*1>31),"Day out of range - dd-mm-yyyy puts the DAY first",IF(OR(MID(TRIM($G7&""),4,2)*1<1,MID(TRIM($G7&""),4,2)*1>12),"Month out of range - dd-mm-yyyy puts the MONTH second",IF(OR(RIGHT(TRIM($G7&""),4)*1<2000,RIGHT(TRIM($G7&""),4)*1>2100),"Year out of range (2000-2100)",IF(DAY(DATE(RIGHT(TRIM($G7&""),4)*1,MID(TRIM($G7&""),4,2)*1,LEFT(TRIM($G7&""),2)*1))<>LEFT(TRIM($G7&""),2)*1,"Not a real calendar date (e.g. 31-02 or 30-02)","OK")))))))))) -> OK | Z7: =IF($P7="","",IF(SUMPRODUCT(--EXACT($P7,Config!$G$2:$G$4))>0,"OK",IF(NOT(ISNA(MATCH($P7,Config!$G$2:$G$4,0))),"WARNING: wrong capitalisation - should be """&INDEX(Config!$G$2:$G$4,MATCH($P7,Config!$G$2:$G$4,0))&""" exactly","Must be one of: Active, Deactivated, Suspended"))) -> OK | AA7: =IF($Q7="","",IF(SUMPRODUCT(--EXACT($Q7,Config!$H$2:$H$3))>0,"OK",IF(NOT(ISNA(MATCH($Q7,Config!$H$2:$H$3,0))),"WARNING: wrong capitalisation - should be """&INDEX(Config!$H$2:$H$3,MATCH($Q7,Config!$H$2:$H$3,0))&""" exactly","Must be one of: eSIM, Physical SIM"))) -> OK | AB7: =IF(IF(OR($T7="",$T7="OK"),"","PhoneNr: "&$T7&" // ")&IF(OR($W7="",$W7="OK"),"","ICC_ID: "&$W7&" // ")&IF(OR($Y7="",$Y7="OK"),"","StartDate: "&$Y7&" // ")&IF(OR($Z7="",$Z7="OK"),"","Status: "&$Z7&" // ")&IF(OR($AA7="",$AA7="OK"),"","SIM Type: "&$AA7&" // ")&IF(OR($X7="",$X7="OK"),"","IMEI: "&$X7&" // ")="","OK",LEFT(IF(OR($T7="",$T7="OK"),"","PhoneNr: "&$T7&" // ")&IF(OR($W7="",$W7="OK"),"","ICC_ID: "&$W7&" // ")&IF(OR($Y7="",$Y7="OK"),"","StartDate: "&$Y7&" // ")&IF(OR($Z7="",$Z7="OK"),"","Status: "&$Z7&" // ")&IF(OR($AA7="",$AA7="OK"),"","SIM Type: "&$AA7&" // ")&IF(OR($X7="",$X7="OK"),"","IMEI: "&$X7&" // "),LEN(IF(OR($T7="",$T7="OK"),"","PhoneNr: "&$T7&" // ")&IF(OR($W7="",$W7="OK"),"","ICC_ID: "&$W7&" // ")&IF(OR($Y7="",$Y7="OK"),"","StartDate: "&$Y7&" // ")&IF(OR($Z7="",$Z7="OK"),"","Status: "&$Z7&" // ")&IF(OR($AA7="",$AA7="OK"),"","SIM Type: "&$AA7&" // ")&IF(OR($X7="",$X7="OK"),"","IMEI: "&$X7&" // "))-6)) -> OK | AD7: PhoneNr: valid, dashes stripped
A8: Marco | B8: Rossi | C8: +39123 | E8: 8935201234567890125 | G8: 15-03-2026 | H8: Italy | P8: Active | Q8: eSIM | T8: =IF($C8="","",IF($V8="","No digits at all - enter a phone number",IF(NOT(SUMPRODUCT(--ISNUMBER(--MID($V8,ROW(INDIRECT("1:"&LEN($V8))),1)))=LEN($V8)),"Digits only - no letters or symbols (+ ( ) - . and spaces are tolerated)",IF(LEN($V8)<8,"Too short - "&LEN($V8)&" digits (min 8)",IF(LEN($V8)>15,"Too long - "&LEN($V8)&" digits (max 15)",IF($H8="","WARNING: SIM_Country is empty - cannot check the country code",IF(ISNA(MATCH($H8,tblCountries[Name],0)),"WARNING: SIM_Country """&$H8&""" is not in tblCountries",IF(LEFT($V8,LEN(TEXT(INDEX(tblCountries[DialCode],MATCH($H8,tblCountries[Name],0)),"0")))<>TEXT(INDEX(tblCountries[DialCode],MATCH($H8,tblCountries[Name],0)),"0"),"Wrong country code - must start with +"&TEXT(INDEX(tblCountries[DialCode],MATCH($H8,tblCountries[Name],0)),"0")&" for "&$H8,"OK")))))))) -> Too short - 5 digits (min 8) | U8: 352099001760897 | V8: =IF($C8="","",IF(LEFT(SUBSTITUTE(SUBSTITUTE(SUBSTITUTE(SUBSTITUTE(SUBSTITUTE(SUBSTITUTE(SUBSTITUTE(TRIM($C8&""),"+","")," ",""),"-",""),"(",""),")",""),".",""),CHAR(160),""),2)="00",MID(SUBSTITUTE(SUBSTITUTE(SUBSTITUTE(SUBSTITUTE(SUBSTITUTE(SUBSTITUTE(SUBSTITUTE(TRIM($C8&""),"+","")," ",""),"-",""),"(",""),")",""),".",""),CHAR(160),""),3,255),SUBSTITUTE(SUBSTITUTE(SUBSTITUTE(SUBSTITUTE(SUBSTITUTE(SUBSTITUTE(SUBSTITUTE(TRIM($C8&""),"+","")," ",""),"-",""),"(",""),")",""),".",""),CHAR(160),""))) -> 39123 | W8: =IF($E8="","",IF(ISNUMBER($E8),"Stored as a NUMBER - every digit past the 15th is already lost. Format the column as Text and re-enter.",IF(NOT(SUMPRODUCT(--ISNUMBER(--MID(TRIM($E8&""),ROW(INDIRECT("1:"&LEN(TRIM($E8&"")))),1)))=LEN(TRIM($E8&""))),"Digits only - no +, -, spaces or any other character",IF(LEFT(TRIM($E8&""),2)<>"89","Must start with 89 (ITU-T E.118 telecom prefix)",IF(LEN(TRIM($E8&""))<18,"Too short - "&LEN(TRIM($E8&""))&" digits (min 18)",IF(LEN(TRIM($E8&""))>22,"Too long - "&LEN(TRIM($E8&""))&" digits (max 22)",IF(NOT(MOD(SUMPRODUCT(MID(TRIM($E8&""),ROW(INDIRECT("1:"&LEN(TRIM($E8&"")))),1)*1*(1+MOD(LEN(TRIM($E8&""))-ROW(INDIRECT("1:"&LEN(TRIM($E8&"")))),2))-MOD(LEN(TRIM($E8&""))-ROW(INDIRECT("1:"&LEN(TRIM($E8&"")))),2)*9*(MID(TRIM($E8&""),ROW(INDIRECT("1:"&LEN(TRIM($E8&"")))),1)*1*2>9)),10)=0),"WARNING: Luhn check digit does not match - likely a typo or a transposition","OK"))))))) -> OK | X8: =IF($U8="","",IF(NOT(SUMPRODUCT(--ISNUMBER(--MID(TRIM($U8&""),ROW(INDIRECT("1:"&LEN(TRIM($U8&"")))),1)))=LEN(TRIM($U8&""))),"Digits only - no +, -, spaces or any other character",IF(LEN(TRIM($U8&""))<>15,"Must be exactly 15 digits - this one has "&LEN(TRIM($U8&"")),IF(NOT(MOD(SUMPRODUCT(MID(TRIM($U8&""),ROW(INDIRECT("1:"&LEN(TRIM($U8&"")))),1)*1*(1+MOD(LEN(TRIM($U8&""))-ROW(INDIRECT("1:"&LEN(TRIM($U8&"")))),2))-MOD(LEN(TRIM($U8&""))-ROW(INDIRECT("1:"&LEN(TRIM($U8&"")))),2)*9*(MID(TRIM($U8&""),ROW(INDIRECT("1:"&LEN(TRIM($U8&"")))),1)*1*2>9)),10)=0),"WARNING: Luhn check digit does not match - likely a typo or a transposition","OK")))) -> OK | Y8: =IF($G8="","",IF(ISNUMBER($G8),IF(OR($G8<DATE(2000,1,1),$G8>TODAY()+730),"WARNING: real date, but outside 2000-01-01 .. today+2y - check the day/month order","OK"),IF(LEN(TRIM($G8&""))<>10,"Must be dd-mm-yyyy - 10 characters, this one has "&LEN(TRIM($G8&"")),IF(AND(NOT(ISERROR(FIND(MID(TRIM($G8&""),5,1),"-/."))),NOT(ISERROR(FIND(MID(TRIM($G8&""),8,1),"-/."))),SUMPRODUCT(--ISNUMBER(--MID(LEFT(TRIM($G8&""),4),ROW(INDIRECT("1:"&LEN(LEFT(TRIM($G8&""),4)))),1)))=LEN(LEFT(TRIM($G8&""),4))),"Looks like yyyy-mm-dd - StartDate must put the DAY first: dd-mm-yyyy",IF(OR(MID(TRIM($G8&""),3,1)<>MID(TRIM($G8&""),6,1),ISERROR(FIND(MID(TRIM($G8&""),3,1),"-/."))),"Separators must be in positions 3 and 6, matching, and be - or / or .",IF(NOT(AND(SUMPRODUCT(--ISNUMBER(--MID(LEFT(TRIM($G8&""),2),ROW(INDIRECT("1:"&LEN(LEFT(TRIM($G8&""),2)))),1)))=LEN(LEFT(TRIM($G8&""),2)),SUMPRODUCT(--ISNUMBER(--MID(MID(TRIM($G8&""),4,2),ROW(INDIRECT("1:"&LEN(MID(TRIM($G8&""),4,2)))),1)))=LEN(MID(TRIM($G8&""),4,2)),SUMPRODUCT(--ISNUMBER(--MID(RIGHT(TRIM($G8&""),4),ROW(INDIRECT("1:"&LEN(RIGHT(TRIM($G8&""),4)))),1)))=LEN(RIGHT(TRIM($G8&""),4)))),"Day, month and year must all be digits",IF(OR(LEFT(TRIM($G8&""),2)*1<1,LEFT(TRIM($G8&""),2)*1>31),"Day out of range - dd-mm-yyyy puts the DAY first",IF(OR(MID(TRIM($G8&""),4,2)*1<1,MID(TRIM($G8&""),4,2)*1>12),"Month out of range - dd-mm-yyyy puts the MONTH second",IF(OR(RIGHT(TRIM($G8&""),4)*1<2000,RIGHT(TRIM($G8&""),4)*1>2100),"Year out of range (2000-2100)",IF(DAY(DATE(RIGHT(TRIM($G8&""),4)*1,MID(TRIM($G8&""),4,2)*1,LEFT(TRIM($G8&""),2)*1))<>LEFT(TRIM($G8&""),2)*1,"Not a real calendar date (e.g. 31-02 or 30-02)","OK")))))))))) -> OK | Z8: =IF($P8="","",IF(SUMPRODUCT(--EXACT($P8,Config!$G$2:$G$4))>0,"OK",IF(NOT(ISNA(MATCH($P8,Config!$G$2:$G$4,0))),"WARNING: wrong capitalisation - should be """&INDEX(Config!$G$2:$G$4,MATCH($P8,Config!$G$2:$G$4,0))&""" exactly","Must be one of: Active, Deactivated, Suspended"))) -> OK | AA8: =IF($Q8="","",IF(SUMPRODUCT(--EXACT($Q8,Config!$H$2:$H$3))>0,"OK",IF(NOT(ISNA(MATCH($Q8,Config!$H$2:$H$3,0))),"WARNING: wrong capitalisation - should be """&INDEX(Config!$H$2:$H$3,MATCH($Q8,Config!$H$2:$H$3,0))&""" exactly","Must be one of: eSIM, Physical SIM"))) -> OK | AB8: =IF(IF(OR($T8="",$T8="OK"),"","PhoneNr: "&$T8&" // ")&IF(OR($W8="",$W8="OK"),"","ICC_ID: "&$W8&" // ")&IF(OR($Y8="",$Y8="OK"),"","StartDate: "&$Y8&" // ")&IF(OR($Z8="",$Z8="OK"),"","Status: "&$Z8&" // ")&IF(OR($AA8="",$AA8="OK"),"","SIM Type: "&$AA8&" // ")&IF(OR($X8="",$X8="OK"),"","IMEI: "&$X8&" // ")="","OK",LEFT(IF(OR($T8="",$T8="OK"),"","PhoneNr: "&$T8&" // ")&IF(OR($W8="",$W8="OK"),"","ICC_ID: "&$W8&" // ")&IF(OR($Y8="",$Y8="OK"),"","StartDate: "&$Y8&" // ")&IF(OR($Z8="",$Z8="OK"),"","Status: "&$Z8&" // ")&IF(OR($AA8="",$AA8="OK"),"","SIM Type: "&$AA8&" // ")&IF(OR($X8="",$X8="OK"),"","IMEI: "&$X8&" // "),LEN(IF(OR($T8="",$T8="OK"),"","PhoneNr: "&$T8&" // ")&IF(OR($W8="",$W8="OK"),"","ICC_ID: "&$W8&" // ")&IF(OR($Y8="",$Y8="OK"),"","StartDate: "&$Y8&" // ")&IF(OR($Z8="",$Z8="OK"),"","Status: "&$Z8&" // ")&IF(OR($AA8="",$AA8="OK"),"","SIM Type: "&$AA8&" // ")&IF(OR($X8="",$X8="OK"),"","IMEI: "&$X8&" // "))-6)) -> PhoneNr: Too short - 5 digits (min 8) | AD8: PhoneNr: too short
A9: Sofia | B9: Garcia | C9: +34123456789012345 | E9: 8935201234567890125 | G9: 15-03-2026 | H9: Spain | P9: Active | Q9: eSIM | T9: =IF($C9="","",IF($V9="","No digits at all - enter a phone number",IF(NOT(SUMPRODUCT(--ISNUMBER(--MID($V9,ROW(INDIRECT("1:"&LEN($V9))),1)))=LEN($V9)),"Digits only - no letters or symbols (+ ( ) - . and spaces are tolerated)",IF(LEN($V9)<8,"Too short - "&LEN($V9)&" digits (min 8)",IF(LEN($V9)>15,"Too long - "&LEN($V9)&" digits (max 15)",IF($H9="","WARNING: SIM_Country is empty - cannot check the country code",IF(ISNA(MATCH($H9,tblCountries[Name],0)),"WARNING: SIM_Country """&$H9&""" is not in tblCountries",IF(LEFT($V9,LEN(TEXT(INDEX(tblCountries[DialCode],MATCH($H9,tblCountries[Name],0)),"0")))<>TEXT(INDEX(tblCountries[DialCode],MATCH($H9,tblCountries[Name],0)),"0"),"Wrong country code - must start with +"&TEXT(INDEX(tblCountries[DialCode],MATCH($H9,tblCountries[Name],0)),"0")&" for "&$H9,"OK")))))))) -> Too long - 17 digits (max 15) | U9: 352099001760897 | V9: =IF($C9="","",IF(LEFT(SUBSTITUTE(SUBSTITUTE(SUBSTITUTE(SUBSTITUTE(SUBSTITUTE(SUBSTITUTE(SUBSTITUTE(TRIM($C9&""),"+","")," ",""),"-",""),"(",""),")",""),".",""),CHAR(160),""),2)="00",MID(SUBSTITUTE(SUBSTITUTE(SUBSTITUTE(SUBSTITUTE(SUBSTITUTE(SUBSTITUTE(SUBSTITUTE(TRIM($C9&""),"+","")," ",""),"-",""),"(",""),")",""),".",""),CHAR(160),""),3,255),SUBSTITUTE(SUBSTITUTE(SUBSTITUTE(SUBSTITUTE(SUBSTITUTE(SUBSTITUTE(SUBSTITUTE(TRIM($C9&""),"+","")," ",""),"-",""),"(",""),")",""),".",""),CHAR(160),""))) -> 34123456789012345 | W9: =IF($E9="","",IF(ISNUMBER($E9),"Stored as a NUMBER - every digit past the 15th is already lost. Format the column as Text and re-enter.",IF(NOT(SUMPRODUCT(--ISNUMBER(--MID(TRIM($E9&""),ROW(INDIRECT("1:"&LEN(TRIM($E9&"")))),1)))=LEN(TRIM($E9&""))),"Digits only - no +, -, spaces or any other character",IF(LEFT(TRIM($E9&""),2)<>"89","Must start with 89 (ITU-T E.118 telecom prefix)",IF(LEN(TRIM($E9&""))<18,"Too short - "&LEN(TRIM($E9&""))&" digits (min 18)",IF(LEN(TRIM($E9&""))>22,"Too long - "&LEN(TRIM($E9&""))&" digits (max 22)",IF(NOT(MOD(SUMPRODUCT(MID(TRIM($E9&""),ROW(INDIRECT("1:"&LEN(TRIM($E9&"")))),1)*1*(1+MOD(LEN(TRIM($E9&""))-ROW(INDIRECT("1:"&LEN(TRIM($E9&"")))),2))-MOD(LEN(TRIM($E9&""))-ROW(INDIRECT("1:"&LEN(TRIM($E9&"")))),2)*9*(MID(TRIM($E9&""),ROW(INDIRECT("1:"&LEN(TRIM($E9&"")))),1)*1*2>9)),10)=0),"WARNING: Luhn check digit does not match - likely a typo or a transposition","OK"))))))) -> OK | X9: =IF($U9="","",IF(NOT(SUMPRODUCT(--ISNUMBER(--MID(TRIM($U9&""),ROW(INDIRECT("1:"&LEN(TRIM($U9&"")))),1)))=LEN(TRIM($U9&""))),"Digits only - no +, -, spaces or any other character",IF(LEN(TRIM($U9&""))<>15,"Must be exactly 15 digits - this one has "&LEN(TRIM($U9&"")),IF(NOT(MOD(SUMPRODUCT(MID(TRIM($U9&""),ROW(INDIRECT("1:"&LEN(TRIM($U9&"")))),1)*1*(1+MOD(LEN(TRIM($U9&""))-ROW(INDIRECT("1:"&LEN(TRIM($U9&"")))),2))-MOD(LEN(TRIM($U9&""))-ROW(INDIRECT("1:"&LEN(TRIM($U9&"")))),2)*9*(MID(TRIM($U9&""),ROW(INDIRECT("1:"&LEN(TRIM($U9&"")))),1)*1*2>9)),10)=0),"WARNING: Luhn check digit does not match - likely a typo or a transposition","OK")))) -> OK | Y9: =IF($G9="","",IF(ISNUMBER($G9),IF(OR($G9<DATE(2000,1,1),$G9>TODAY()+730),"WARNING: real date, but outside 2000-01-01 .. today+2y - check the day/month order","OK"),IF(LEN(TRIM($G9&""))<>10,"Must be dd-mm-yyyy - 10 characters, this one has "&LEN(TRIM($G9&"")),IF(AND(NOT(ISERROR(FIND(MID(TRIM($G9&""),5,1),"-/."))),NOT(ISERROR(FIND(MID(TRIM($G9&""),8,1),"-/."))),SUMPRODUCT(--ISNUMBER(--MID(LEFT(TRIM($G9&""),4),ROW(INDIRECT("1:"&LEN(LEFT(TRIM($G9&""),4)))),1)))=LEN(LEFT(TRIM($G9&""),4))),"Looks like yyyy-mm-dd - StartDate must put the DAY first: dd-mm-yyyy",IF(OR(MID(TRIM($G9&""),3,1)<>MID(TRIM($G9&""),6,1),ISERROR(FIND(MID(TRIM($G9&""),3,1),"-/."))),"Separators must be in positions 3 and 6, matching, and be - or / or .",IF(NOT(AND(SUMPRODUCT(--ISNUMBER(--MID(LEFT(TRIM($G9&""),2),ROW(INDIRECT("1:"&LEN(LEFT(TRIM($G9&""),2)))),1)))=LEN(LEFT(TRIM($G9&""),2)),SUMPRODUCT(--ISNUMBER(--MID(MID(TRIM($G9&""),4,2),ROW(INDIRECT("1:"&LEN(MID(TRIM($G9&""),4,2)))),1)))=LEN(MID(TRIM($G9&""),4,2)),SUMPRODUCT(--ISNUMBER(--MID(RIGHT(TRIM($G9&""),4),ROW(INDIRECT("1:"&LEN(RIGHT(TRIM($G9&""),4)))),1)))=LEN(RIGHT(TRIM($G9&""),4)))),"Day, month and year must all be digits",IF(OR(LEFT(TRIM($G9&""),2)*1<1,LEFT(TRIM($G9&""),2)*1>31),"Day out of range - dd-mm-yyyy puts the DAY first",IF(OR(MID(TRIM($G9&""),4,2)*1<1,MID(TRIM($G9&""),4,2)*1>12),"Month out of range - dd-mm-yyyy puts the MONTH second",IF(OR(RIGHT(TRIM($G9&""),4)*1<2000,RIGHT(TRIM($G9&""),4)*1>2100),"Year out of range (2000-2100)",IF(DAY(DATE(RIGHT(TRIM($G9&""),4)*1,MID(TRIM($G9&""),4,2)*1,LEFT(TRIM($G9&""),2)*1))<>LEFT(TRIM($G9&""),2)*1,"Not a real calendar date (e.g. 31-02 or 30-02)","OK")))))))))) -> OK | Z9: =IF($P9="","",IF(SUMPRODUCT(--EXACT($P9,Config!$G$2:$G$4))>0,"OK",IF(NOT(ISNA(MATCH($P9,Config!$G$2:$G$4,0))),"WARNING: wrong capitalisation - should be """&INDEX(Config!$G$2:$G$4,MATCH($P9,Config!$G$2:$G$4,0))&""" exactly","Must be one of: Active, Deactivated, Suspended"))) -> OK | AA9: =IF($Q9="","",IF(SUMPRODUCT(--EXACT($Q9,Config!$H$2:$H$3))>0,"OK",IF(NOT(ISNA(MATCH($Q9,Config!$H$2:$H$3,0))),"WARNING: wrong capitalisation - should be """&INDEX(Config!$H$2:$H$3,MATCH($Q9,Config!$H$2:$H$3,0))&""" exactly","Must be one of: eSIM, Physical SIM"))) -> OK | AB9: =IF(IF(OR($T9="",$T9="OK"),"","PhoneNr: "&$T9&" // ")&IF(OR($W9="",$W9="OK"),"","ICC_ID: "&$W9&" // ")&IF(OR($Y9="",$Y9="OK"),"","StartDate: "&$Y9&" // ")&IF(OR($Z9="",$Z9="OK"),"","Status: "&$Z9&" // ")&IF(OR($AA9="",$AA9="OK"),"","SIM Type: "&$AA9&" // ")&IF(OR($X9="",$X9="OK"),"","IMEI: "&$X9&" // ")="","OK",LEFT(IF(OR($T9="",$T9="OK"),"","PhoneNr: "&$T9&" // ")&IF(OR($W9="",$W9="OK"),"","ICC_ID: "&$W9&" // ")&IF(OR($Y9="",$Y9="OK"),"","StartDate: "&$Y9&" // ")&IF(OR($Z9="",$Z9="OK"),"","Status: "&$Z9&" // ")&IF(OR($AA9="",$AA9="OK"),"","SIM Type: "&$AA9&" // ")&IF(OR($X9="",$X9="OK"),"","IMEI: "&$X9&" // "),LEN(IF(OR($T9="",$T9="OK"),"","PhoneNr: "&$T9&" // ")&IF(OR($W9="",$W9="OK"),"","ICC_ID: "&$W9&" // ")&IF(OR($Y9="",$Y9="OK"),"","StartDate: "&$Y9&" // ")&IF(OR($Z9="",$Z9="OK"),"","Status: "&$Z9&" // ")&IF(OR($AA9="",$AA9="OK"),"","SIM Type: "&$AA9&" // ")&IF(OR($X9="",$X9="OK"),"","IMEI: "&$X9&" // "))-6)) -> PhoneNr: Too long - 17 digits (max 15) | AD9: PhoneNr: too long
